2024-10-15 07:12:10,554 - /media/aa/A/coffee/co/main/forms.py changed, reloading.
2024-10-15 07:24:17,862 - Internal Server Error: /
Traceback (most recent call last):
  File "/home/aa/.local/lib/python3.10/site-packages/django/core/handlers/exception.py", line 55, in inner
    response = get_response(request)
  File "/home/aa/.local/lib/python3.10/site-packages/django/core/handlers/base.py", line 197, in _get_response
    response = wrapped_callback(request, *callback_args, **callback_kwargs)
  File "/media/aa/A/coffee/co/main/views.py", line 8, in index
    callme_form = handle_callme_form(request)
  File "/media/aa/A/coffee/co/main/form_generator.py", line 19, in handle_callme_form
    callme = CallMe(
NameError: name 'CallMe' is not defined
2024-10-15 07:24:51,190 - /media/aa/A/coffee/co/main/forms.py changed, reloading.
2024-10-15 07:25:19,535 - /media/aa/A/coffee/co/main/models.py changed, reloading.
2024-10-15 07:25:53,209 - Internal Server Error: /
Traceback (most recent call last):
  File "/home/aa/.local/lib/python3.10/site-packages/django/core/handlers/exception.py", line 55, in inner
    response = get_response(request)
  File "/home/aa/.local/lib/python3.10/site-packages/django/core/handlers/base.py", line 197, in _get_response
    response = wrapped_callback(request, *callback_args, **callback_kwargs)
  File "/media/aa/A/coffee/co/main/views.py", line 8, in index
    callme_form = handle_callme_form(request)
  File "/media/aa/A/coffee/co/main/form_generator.py", line 24, in handle_callme_form
    callme_created.delay(callme.id)
NameError: name 'callme_created' is not defined
2024-10-15 07:26:10,334 - Internal Server Error: /
Traceback (most recent call last):
  File "/home/aa/.local/lib/python3.10/site-packages/django/core/handlers/exception.py", line 55, in inner
    response = get_response(request)
  File "/home/aa/.local/lib/python3.10/site-packages/django/core/handlers/base.py", line 197, in _get_response
    response = wrapped_callback(request, *callback_args, **callback_kwargs)
  File "/media/aa/A/coffee/co/main/views.py", line 8, in index
    callme_form = handle_callme_form(request)
  File "/media/aa/A/coffee/co/main/form_generator.py", line 24, in handle_callme_form
    callme_created.delay(callme.id)
NameError: name 'callme_created' is not defined
2024-10-15 07:26:51,193 - /media/aa/A/coffee/co/main/tasks.py changed, reloading.
2024-10-15 07:26:58,243 - /media/aa/A/coffee/co/main/form_generator.py changed, reloading.
2024-10-15 07:27:04,177 - Internal Server Error: /
Traceback (most recent call last):
  File "/home/aa/.local/lib/python3.10/site-packages/django/core/handlers/exception.py", line 55, in inner
    response = get_response(request)
  File "/home/aa/.local/lib/python3.10/site-packages/django/core/handlers/base.py", line 197, in _get_response
    response = wrapped_callback(request, *callback_args, **callback_kwargs)
  File "/media/aa/A/coffee/co/main/views.py", line 8, in index
    callme_form = handle_callme_form(request)
  File "/media/aa/A/coffee/co/main/form_generator.py", line 24, in handle_callme_form
    send_email.delay(callme.id)
  File "/home/aa/.local/lib/python3.10/site-packages/celery/app/task.py", line 444, in delay
    return self.apply_async(args, kwargs)
  File "/home/aa/.local/lib/python3.10/site-packages/celery/app/task.py", line 559, in apply_async
    check_arguments(*(args or ()), **(kwargs or {}))
TypeError: send_email() missing 2 required positional arguments: 'email' and 'message'
2024-10-15 07:28:10,081 - /media/aa/A/coffee/co/main/views.py changed, reloading.
2024-10-15 07:29:06,197 - Internal Server Error: /
Traceback (most recent call last):
  File "/home/aa/.local/lib/python3.10/site-packages/django/core/handlers/exception.py", line 55, in inner
    response = get_response(request)
  File "/home/aa/.local/lib/python3.10/site-packages/django/core/handlers/base.py", line 197, in _get_response
    response = wrapped_callback(request, *callback_args, **callback_kwargs)
  File "/media/aa/A/coffee/co/main/views.py", line 8, in index
    callme_form = handle_callme_form(request)
  File "/media/aa/A/coffee/co/main/form_generator.py", line 24, in handle_callme_form
    send_email.delay(callme.id)
  File "/home/aa/.local/lib/python3.10/site-packages/celery/app/task.py", line 444, in delay
    return self.apply_async(args, kwargs)
  File "/home/aa/.local/lib/python3.10/site-packages/celery/app/task.py", line 559, in apply_async
    check_arguments(*(args or ()), **(kwargs or {}))
TypeError: send_email() missing 2 required positional arguments: 'email' and 'message'
2024-10-15 07:30:46,164 - /media/aa/A/coffee/co/main/form_generator.py changed, reloading.
2024-10-15 08:05:44,824 - /media/aa/A/coffee/co/main/views.py changed, reloading.
2024-10-15 08:09:07,798 - /media/aa/A/coffee/co/main/form_generator.py changed, reloading.
2024-10-15 08:10:39,608 - /media/aa/A/coffee/co/main/form_generator.py changed, reloading.
2024-10-15 08:11:04,895 - /media/aa/A/coffee/co/main/form_generator.py changed, reloading.
2024-10-15 08:11:24,818 - Internal Server Error: /
Traceback (most recent call last):
  File "/home/aa/.local/lib/python3.10/site-packages/django/core/handlers/exception.py", line 55, in inner
    response = get_response(request)
  File "/home/aa/.local/lib/python3.10/site-packages/django/core/handlers/base.py", line 197, in _get_response
    response = wrapped_callback(request, *callback_args, **callback_kwargs)
  File "/media/aa/A/coffee/co/main/views.py", line 8, in index
    callme_form = handle_callme_form(request)
  File "/media/aa/A/coffee/co/main/form_generator.py", line 25, in handle_callme_form
    first_name=callme_form.cleaned_data.get['first_name'],
TypeError: 'builtin_function_or_method' object is not subscriptable
2024-10-15 08:11:41,439 - /media/aa/A/coffee/co/main/form_generator.py changed, reloading.
2024-10-15 08:11:45,455 - Internal Server Error: /
Traceback (most recent call last):
  File "/home/aa/.local/lib/python3.10/site-packages/django/core/handlers/exception.py", line 55, in inner
    response = get_response(request)
  File "/home/aa/.local/lib/python3.10/site-packages/django/core/handlers/base.py", line 197, in _get_response
    response = wrapped_callback(request, *callback_args, **callback_kwargs)
  File "/media/aa/A/coffee/co/main/views.py", line 8, in index
    callme_form = handle_callme_form(request)
  File "/media/aa/A/coffee/co/main/form_generator.py", line 25, in handle_callme_form
    first_name=callme_form.cleaned_data.get['first_name'],
TypeError: 'builtin_function_or_method' object is not subscriptable
2024-10-15 08:15:04,159 - /media/aa/A/coffee/co/main/form_generator.py changed, reloading.
2024-10-15 08:17:15,756 - /media/aa/A/coffee/co/main/form_generator.py changed, reloading.
2024-10-15 08:18:41,348 - Internal Server Error: /
Traceback (most recent call last):
  File "/home/aa/.local/lib/python3.10/site-packages/django/core/handlers/exception.py", line 55, in inner
    response = get_response(request)
  File "/home/aa/.local/lib/python3.10/site-packages/django/core/handlers/base.py", line 197, in _get_response
    response = wrapped_callback(request, *callback_args, **callback_kwargs)
  File "/media/aa/A/coffee/co/main/views.py", line 8, in index
    callme_form = handle_callme_form(request)
  File "/media/aa/A/coffee/co/main/form_generator.py", line 19, in handle_callme_form
    callme_order = callme.save()
NameError: name 'callme' is not defined
2024-10-15 08:19:05,880 - /media/aa/A/coffee/co/main/form_generator.py changed, reloading.
2024-10-15 08:19:09,577 - Internal Server Error: /
Traceback (most recent call last):
  File "/home/aa/.local/lib/python3.10/site-packages/django/core/handlers/exception.py", line 55, in inner
    response = get_response(request)
  File "/home/aa/.local/lib/python3.10/site-packages/django/core/handlers/base.py", line 197, in _get_response
    response = wrapped_callback(request, *callback_args, **callback_kwargs)
  File "/media/aa/A/coffee/co/main/views.py", line 8, in index
    callme_form = handle_callme_form(request)
  File "/media/aa/A/coffee/co/main/form_generator.py", line 19, in handle_callme_form
    callme_order = callme_form.save()
AttributeError: 'CallMeForm' object has no attribute 'save'
2024-10-15 10:34:49,146 - Internal Server Error: /
Traceback (most recent call last):
  File "/home/aa/.local/lib/python3.10/site-packages/django/core/handlers/exception.py", line 55, in inner
    response = get_response(request)
  File "/home/aa/.local/lib/python3.10/site-packages/django/core/handlers/base.py", line 197, in _get_response
    response = wrapped_callback(request, *callback_args, **callback_kwargs)
  File "/media/aa/A/coffee/co/main/views.py", line 8, in index
    callme_form = handle_callme_form(request)
  File "/media/aa/A/coffee/co/main/form_generator.py", line 19, in handle_callme_form
    callme_order = callme_form.save()
AttributeError: 'CallMeForm' object has no attribute 'save'
2024-10-15 11:07:12,689 - /media/aa/A/coffee/co/main/forms.py changed, reloading.
2024-10-15 11:11:06,468 - Internal Server Error: /
Traceback (most recent call last):
  File "/home/aa/.local/lib/python3.10/site-packages/django/core/handlers/exception.py", line 55, in inner
    response = get_response(request)
  File "/home/aa/.local/lib/python3.10/site-packages/django/core/handlers/base.py", line 197, in _get_response
    response = wrapped_callback(request, *callback_args, **callback_kwargs)
  File "/media/aa/A/coffee/co/main/views.py", line 8, in index
    callme_form = handle_callme_form(request)
  File "/media/aa/A/coffee/co/main/form_generator.py", line 19, in handle_callme_form
    callme_order = callme_form.save()
AttributeError: 'CallMeForm' object has no attribute 'save'
2024-10-15 11:12:39,738 - /media/aa/A/coffee/co/main/models.py changed, reloading.
2024-10-15 11:12:58,967 - /media/aa/A/coffee/co/main/models.py changed, reloading.
2024-10-15 11:13:24,261 - /media/aa/A/coffee/co/main/models.py changed, reloading.
2024-10-15 11:13:30,324 - /media/aa/A/coffee/co/main/models.py changed, reloading.
2024-10-15 11:15:14,513 - /media/aa/A/coffee/co/main/forms.py changed, reloading.
2024-10-15 11:15:34,728 - /media/aa/A/coffee/co/main/forms.py changed, reloading.
2024-10-15 11:16:28,413 - Internal Server Error: /
Traceback (most recent call last):
  File "/home/aa/.local/lib/python3.10/site-packages/django/core/handlers/exception.py", line 55, in inner
    response = get_response(request)
  File "/home/aa/.local/lib/python3.10/site-packages/django/core/handlers/base.py", line 197, in _get_response
    response = wrapped_callback(request, *callback_args, **callback_kwargs)
  File "/media/aa/A/coffee/co/main/views.py", line 8, in index
    callme_form = handle_callme_form(request)
  File "/media/aa/A/coffee/co/main/form_generator.py", line 19, in handle_callme_form
    callme_order = callme_form.save()
AttributeError: 'CallMeForm' object has no attribute 'save'
2024-10-15 11:16:55,646 - /media/aa/A/coffee/co/main/models.py changed, reloading.
2024-10-15 11:17:32,950 - Internal Server Error: /
Traceback (most recent call last):
  File "/home/aa/.local/lib/python3.10/site-packages/django/core/handlers/exception.py", line 55, in inner
    response = get_response(request)
  File "/home/aa/.local/lib/python3.10/site-packages/django/core/handlers/base.py", line 197, in _get_response
    response = wrapped_callback(request, *callback_args, **callback_kwargs)
  File "/media/aa/A/coffee/co/main/views.py", line 8, in index
    callme_form = handle_callme_form(request)
  File "/media/aa/A/coffee/co/main/form_generator.py", line 19, in handle_callme_form
    callme_order = callme_form.save()
AttributeError: 'CallMeForm' object has no attribute 'save'
2024-10-15 11:18:31,965 - /media/aa/A/coffee/co/main/forms.py changed, reloading.
2024-10-15 11:19:14,452 - /media/aa/A/coffee/co/main/models.py changed, reloading.
2024-10-15 11:19:18,495 - /media/aa/A/coffee/co/main/models.py changed, reloading.
2024-10-15 11:19:35,733 - Internal Server Error: /
Traceback (most recent call last):
  File "/home/aa/.local/lib/python3.10/site-packages/django/core/handlers/exception.py", line 55, in inner
    response = get_response(request)
  File "/home/aa/.local/lib/python3.10/site-packages/django/core/handlers/base.py", line 197, in _get_response
    response = wrapped_callback(request, *callback_args, **callback_kwargs)
  File "/media/aa/A/coffee/co/main/views.py", line 8, in index
    callme_form = handle_callme_form(request)
  File "/media/aa/A/coffee/co/main/form_generator.py", line 19, in handle_callme_form
    callme_order = callme_form.save()
AttributeError: 'CallMeForm' object has no attribute 'save'
2024-10-15 11:22:05,745 - /media/aa/A/coffee/co/main/form_generator.py changed, reloading.
2024-10-15 11:22:44,743 - Internal Server Error: /
Traceback (most recent call last):
  File "/home/aa/.local/lib/python3.10/site-packages/django/core/handlers/exception.py", line 55, in inner
    response = get_response(request)
  File "/home/aa/.local/lib/python3.10/site-packages/django/core/handlers/base.py", line 197, in _get_response
    response = wrapped_callback(request, *callback_args, **callback_kwargs)
  File "/media/aa/A/coffee/co/main/views.py", line 8, in index
    callme_form = handle_callme_form(request)
  File "/media/aa/A/coffee/co/main/form_generator.py", line 19, in handle_callme_form
    callme_order = callme_form.save()  # This will save the form data to the database
AttributeError: 'CallMeForm' object has no attribute 'save'
2024-10-15 11:22:53,636 - Internal Server Error: /
Traceback (most recent call last):
  File "/home/aa/.local/lib/python3.10/site-packages/django/core/handlers/exception.py", line 55, in inner
    response = get_response(request)
  File "/home/aa/.local/lib/python3.10/site-packages/django/core/handlers/base.py", line 197, in _get_response
    response = wrapped_callback(request, *callback_args, **callback_kwargs)
  File "/media/aa/A/coffee/co/main/views.py", line 8, in index
    callme_form = handle_callme_form(request)
  File "/media/aa/A/coffee/co/main/form_generator.py", line 19, in handle_callme_form
    callme_order = callme_form.save()  # This will save the form data to the database
AttributeError: 'CallMeForm' object has no attribute 'save'
2024-10-15 11:26:55,734 - /media/aa/A/coffee/co/main/form_generator.py changed, reloading.
2024-10-15 11:27:02,800 - /media/aa/A/coffee/co/main/form_generator.py changed, reloading.
2024-10-15 11:27:49,360 - /media/aa/A/coffee/co/main/form_generator.py changed, reloading.
2024-10-15 11:28:06,541 - /media/aa/A/coffee/co/main/form_generator.py changed, reloading.
2024-10-15 11:29:43,757 - /media/aa/A/coffee/co/main/forms.py changed, reloading.
2024-10-15 11:30:04,016 - /media/aa/A/coffee/co/main/models.py changed, reloading.
2024-10-15 11:30:24,096 - Not Found: /favicon.ico
2024-10-15 11:33:16,442 - /media/aa/A/coffee/co/main/forms.py changed, reloading.
2024-10-15 11:33:31,604 - /media/aa/A/coffee/co/main/forms.py changed, reloading.
2024-10-15 11:33:45,795 - Mail to manager sent successfully!!!
2024-10-15 11:36:36,012 - /media/aa/A/coffee/co/main/admin.py changed, reloading.
2024-10-15 11:37:17,279 - /media/aa/A/coffee/co/main/admin.py changed, reloading.
2024-10-15 11:42:12,312 - /media/aa/A/coffee/co/main/form_generator.py changed, reloading.
2024-10-15 11:43:31,269 - /media/aa/A/coffee/co/main/form_generator.py changed, reloading.
2024-10-15 11:44:27,868 - /media/aa/A/coffee/co/main/form_generator.py changed, reloading.
2024-10-15 11:48:09,687 - /media/aa/A/coffee/co/co/settings.py changed, reloading.
2024-10-15 11:48:52,225 - /media/aa/A/coffee/co/main/tasks.py changed, reloading.
2024-10-15 11:50:05,040 - /media/aa/A/coffee/co/main/tasks.py changed, reloading.
2024-10-15 11:50:47,553 - /media/aa/A/coffee/co/main/form_generator.py changed, reloading.
2024-10-15 11:51:50,093 - /media/aa/A/coffee/co/main/tasks.py changed, reloading.
2024-10-15 11:52:11,298 - /media/aa/A/coffee/co/main/tasks.py changed, reloading.
2024-10-15 11:54:35,318 - No hostname was supplied. Reverting to default 'localhost'
2024-10-15 11:54:41,440 - Internal Server Error: /
Traceback (most recent call last):
  File "/home/aa/.local/lib/python3.10/site-packages/kombu/utils/functional.py", line 32, in __call__
    return self.__value__
AttributeError: 'ChannelPromise' object has no attribute '__value__'

During handling of the above exception, another exception occurred:

Traceback (most recent call last):
  File "/home/aa/.local/lib/python3.10/site-packages/kombu/connection.py", line 472, in _reraise_as_library_errors
    yield
  File "/home/aa/.local/lib/python3.10/site-packages/kombu/connection.py", line 459, in _ensure_connection
    return retry_over_time(
  File "/home/aa/.local/lib/python3.10/site-packages/kombu/utils/functional.py", line 318, in retry_over_time
    return fun(*args, **kwargs)
  File "/home/aa/.local/lib/python3.10/site-packages/kombu/connection.py", line 934, in _connection_factory
    self._connection = self._establish_connection()
  File "/home/aa/.local/lib/python3.10/site-packages/kombu/connection.py", line 860, in _establish_connection
    conn = self.transport.establish_connection()
  File "/home/aa/.local/lib/python3.10/site-packages/kombu/transport/pyamqp.py", line 203, in establish_connection
    conn.connect()
  File "/home/aa/.local/lib/python3.10/site-packages/amqp/connection.py", line 324, in connect
    self.transport.connect()
  File "/home/aa/.local/lib/python3.10/site-packages/amqp/transport.py", line 129, in connect
    self._connect(self.host, self.port, self.connect_timeout)
  File "/home/aa/.local/lib/python3.10/site-packages/amqp/transport.py", line 184, in _connect
    self.sock.connect(sa)
ConnectionRefusedError: [Errno 111] Connection refused

The above exception was the direct cause of the following exception:

Traceback (most recent call last):
  File "/home/aa/.local/lib/python3.10/site-packages/django/core/handlers/exception.py", line 55, in inner
    response = get_response(request)
  File "/home/aa/.local/lib/python3.10/site-packages/django/core/handlers/base.py", line 197, in _get_response
    response = wrapped_callback(request, *callback_args, **callback_kwargs)
  File "/media/aa/A/coffee/co/main/views.py", line 8, in index
    callme_form = handle_callme_form(request)
  File "/media/aa/A/coffee/co/main/form_generator.py", line 25, in handle_callme_form
    send_email.delay(name, phone, message)
  File "/home/aa/.local/lib/python3.10/site-packages/celery/app/task.py", line 444, in delay
    return self.apply_async(args, kwargs)
  File "/home/aa/.local/lib/python3.10/site-packages/celery/app/task.py", line 594, in apply_async
    return app.send_task(
  File "/home/aa/.local/lib/python3.10/site-packages/celery/app/base.py", line 801, in send_task
    amqp.send_task_message(P, name, message, **options)
  File "/home/aa/.local/lib/python3.10/site-packages/celery/app/amqp.py", line 518, in send_task_message
    ret = producer.publish(
  File "/home/aa/.local/lib/python3.10/site-packages/kombu/messaging.py", line 186, in publish
    return _publish(
  File "/home/aa/.local/lib/python3.10/site-packages/kombu/connection.py", line 556, in _ensured
    return fun(*args, **kwargs)
  File "/home/aa/.local/lib/python3.10/site-packages/kombu/messaging.py", line 195, in _publish
    channel = self.channel
  File "/home/aa/.local/lib/python3.10/site-packages/kombu/messaging.py", line 218, in _get_channel
    channel = self._channel = channel()
  File "/home/aa/.local/lib/python3.10/site-packages/kombu/utils/functional.py", line 34, in __call__
    value = self.__value__ = self.__contract__()
  File "/home/aa/.local/lib/python3.10/site-packages/kombu/messaging.py", line 234, in <lambda>
    channel = ChannelPromise(lambda: connection.default_channel)
  File "/home/aa/.local/lib/python3.10/site-packages/kombu/connection.py", line 953, in default_channel
    self._ensure_connection(**conn_opts)
  File "/home/aa/.local/lib/python3.10/site-packages/kombu/connection.py", line 458, in _ensure_connection
    with ctx():
  File "/usr/lib/python3.10/contextlib.py", line 153, in __exit__
    self.gen.throw(typ, value, traceback)
  File "/home/aa/.local/lib/python3.10/site-packages/kombu/connection.py", line 476, in _reraise_as_library_errors
    raise ConnectionError(str(exc)) from exc
kombu.exceptions.OperationalError: [Errno 111] Connection refused
2024-10-15 11:58:43,557 - No hostname was supplied. Reverting to default 'localhost'
2024-10-15 11:58:49,646 - Internal Server Error: /
Traceback (most recent call last):
  File "/home/aa/.local/lib/python3.10/site-packages/kombu/utils/functional.py", line 32, in __call__
    return self.__value__
AttributeError: 'ChannelPromise' object has no attribute '__value__'

During handling of the above exception, another exception occurred:

Traceback (most recent call last):
  File "/home/aa/.local/lib/python3.10/site-packages/kombu/connection.py", line 472, in _reraise_as_library_errors
    yield
  File "/home/aa/.local/lib/python3.10/site-packages/kombu/connection.py", line 459, in _ensure_connection
    return retry_over_time(
  File "/home/aa/.local/lib/python3.10/site-packages/kombu/utils/functional.py", line 318, in retry_over_time
    return fun(*args, **kwargs)
  File "/home/aa/.local/lib/python3.10/site-packages/kombu/connection.py", line 934, in _connection_factory
    self._connection = self._establish_connection()
  File "/home/aa/.local/lib/python3.10/site-packages/kombu/connection.py", line 860, in _establish_connection
    conn = self.transport.establish_connection()
  File "/home/aa/.local/lib/python3.10/site-packages/kombu/transport/pyamqp.py", line 203, in establish_connection
    conn.connect()
  File "/home/aa/.local/lib/python3.10/site-packages/amqp/connection.py", line 324, in connect
    self.transport.connect()
  File "/home/aa/.local/lib/python3.10/site-packages/amqp/transport.py", line 129, in connect
    self._connect(self.host, self.port, self.connect_timeout)
  File "/home/aa/.local/lib/python3.10/site-packages/amqp/transport.py", line 184, in _connect
    self.sock.connect(sa)
ConnectionRefusedError: [Errno 111] Connection refused

The above exception was the direct cause of the following exception:

Traceback (most recent call last):
  File "/home/aa/.local/lib/python3.10/site-packages/django/core/handlers/exception.py", line 55, in inner
    response = get_response(request)
  File "/home/aa/.local/lib/python3.10/site-packages/django/core/handlers/base.py", line 197, in _get_response
    response = wrapped_callback(request, *callback_args, **callback_kwargs)
  File "/media/aa/A/coffee/co/main/views.py", line 8, in index
    callme_form = handle_callme_form(request)
  File "/media/aa/A/coffee/co/main/form_generator.py", line 25, in handle_callme_form
    send_email.delay(name, phone, message)
  File "/home/aa/.local/lib/python3.10/site-packages/celery/app/task.py", line 444, in delay
    return self.apply_async(args, kwargs)
  File "/home/aa/.local/lib/python3.10/site-packages/celery/app/task.py", line 594, in apply_async
    return app.send_task(
  File "/home/aa/.local/lib/python3.10/site-packages/celery/app/base.py", line 801, in send_task
    amqp.send_task_message(P, name, message, **options)
  File "/home/aa/.local/lib/python3.10/site-packages/celery/app/amqp.py", line 518, in send_task_message
    ret = producer.publish(
  File "/home/aa/.local/lib/python3.10/site-packages/kombu/messaging.py", line 186, in publish
    return _publish(
  File "/home/aa/.local/lib/python3.10/site-packages/kombu/connection.py", line 556, in _ensured
    return fun(*args, **kwargs)
  File "/home/aa/.local/lib/python3.10/site-packages/kombu/messaging.py", line 195, in _publish
    channel = self.channel
  File "/home/aa/.local/lib/python3.10/site-packages/kombu/messaging.py", line 218, in _get_channel
    channel = self._channel = channel()
  File "/home/aa/.local/lib/python3.10/site-packages/kombu/utils/functional.py", line 34, in __call__
    value = self.__value__ = self.__contract__()
  File "/home/aa/.local/lib/python3.10/site-packages/kombu/messaging.py", line 234, in <lambda>
    channel = ChannelPromise(lambda: connection.default_channel)
  File "/home/aa/.local/lib/python3.10/site-packages/kombu/connection.py", line 953, in default_channel
    self._ensure_connection(**conn_opts)
  File "/home/aa/.local/lib/python3.10/site-packages/kombu/connection.py", line 458, in _ensure_connection
    with ctx():
  File "/usr/lib/python3.10/contextlib.py", line 153, in __exit__
    self.gen.throw(typ, value, traceback)
  File "/home/aa/.local/lib/python3.10/site-packages/kombu/connection.py", line 476, in _reraise_as_library_errors
    raise ConnectionError(str(exc)) from exc
kombu.exceptions.OperationalError: [Errno 111] Connection refused
2024-10-15 11:59:48,847 - /media/aa/A/coffee/co/co/settings.py changed, reloading.
2024-10-15 11:59:57,154 - No hostname was supplied. Reverting to default 'localhost'
2024-10-15 12:00:03,258 - Internal Server Error: /
Traceback (most recent call last):
  File "/home/aa/.local/lib/python3.10/site-packages/kombu/utils/functional.py", line 32, in __call__
    return self.__value__
AttributeError: 'ChannelPromise' object has no attribute '__value__'

During handling of the above exception, another exception occurred:

Traceback (most recent call last):
  File "/home/aa/.local/lib/python3.10/site-packages/kombu/connection.py", line 472, in _reraise_as_library_errors
    yield
  File "/home/aa/.local/lib/python3.10/site-packages/kombu/connection.py", line 459, in _ensure_connection
    return retry_over_time(
  File "/home/aa/.local/lib/python3.10/site-packages/kombu/utils/functional.py", line 318, in retry_over_time
    return fun(*args, **kwargs)
  File "/home/aa/.local/lib/python3.10/site-packages/kombu/connection.py", line 934, in _connection_factory
    self._connection = self._establish_connection()
  File "/home/aa/.local/lib/python3.10/site-packages/kombu/connection.py", line 860, in _establish_connection
    conn = self.transport.establish_connection()
  File "/home/aa/.local/lib/python3.10/site-packages/kombu/transport/pyamqp.py", line 203, in establish_connection
    conn.connect()
  File "/home/aa/.local/lib/python3.10/site-packages/amqp/connection.py", line 324, in connect
    self.transport.connect()
  File "/home/aa/.local/lib/python3.10/site-packages/amqp/transport.py", line 129, in connect
    self._connect(self.host, self.port, self.connect_timeout)
  File "/home/aa/.local/lib/python3.10/site-packages/amqp/transport.py", line 184, in _connect
    self.sock.connect(sa)
ConnectionRefusedError: [Errno 111] Connection refused

The above exception was the direct cause of the following exception:

Traceback (most recent call last):
  File "/home/aa/.local/lib/python3.10/site-packages/django/core/handlers/exception.py", line 55, in inner
    response = get_response(request)
  File "/home/aa/.local/lib/python3.10/site-packages/django/core/handlers/base.py", line 197, in _get_response
    response = wrapped_callback(request, *callback_args, **callback_kwargs)
  File "/media/aa/A/coffee/co/main/views.py", line 8, in index
    callme_form = handle_callme_form(request)
  File "/media/aa/A/coffee/co/main/form_generator.py", line 25, in handle_callme_form
    send_email.delay(name, phone, message)
  File "/home/aa/.local/lib/python3.10/site-packages/celery/app/task.py", line 444, in delay
    return self.apply_async(args, kwargs)
  File "/home/aa/.local/lib/python3.10/site-packages/celery/app/task.py", line 594, in apply_async
    return app.send_task(
  File "/home/aa/.local/lib/python3.10/site-packages/celery/app/base.py", line 801, in send_task
    amqp.send_task_message(P, name, message, **options)
  File "/home/aa/.local/lib/python3.10/site-packages/celery/app/amqp.py", line 518, in send_task_message
    ret = producer.publish(
  File "/home/aa/.local/lib/python3.10/site-packages/kombu/messaging.py", line 186, in publish
    return _publish(
  File "/home/aa/.local/lib/python3.10/site-packages/kombu/connection.py", line 556, in _ensured
    return fun(*args, **kwargs)
  File "/home/aa/.local/lib/python3.10/site-packages/kombu/messaging.py", line 195, in _publish
    channel = self.channel
  File "/home/aa/.local/lib/python3.10/site-packages/kombu/messaging.py", line 218, in _get_channel
    channel = self._channel = channel()
  File "/home/aa/.local/lib/python3.10/site-packages/kombu/utils/functional.py", line 34, in __call__
    value = self.__value__ = self.__contract__()
  File "/home/aa/.local/lib/python3.10/site-packages/kombu/messaging.py", line 234, in <lambda>
    channel = ChannelPromise(lambda: connection.default_channel)
  File "/home/aa/.local/lib/python3.10/site-packages/kombu/connection.py", line 953, in default_channel
    self._ensure_connection(**conn_opts)
  File "/home/aa/.local/lib/python3.10/site-packages/kombu/connection.py", line 458, in _ensure_connection
    with ctx():
  File "/usr/lib/python3.10/contextlib.py", line 153, in __exit__
    self.gen.throw(typ, value, traceback)
  File "/home/aa/.local/lib/python3.10/site-packages/kombu/connection.py", line 476, in _reraise_as_library_errors
    raise ConnectionError(str(exc)) from exc
kombu.exceptions.OperationalError: [Errno 111] Connection refused
2024-10-15 12:00:03,372 - Not Found: /favicon.ico
2024-10-15 12:00:22,918 - Internal Server Error: /
Traceback (most recent call last):
  File "/home/aa/.local/lib/python3.10/site-packages/kombu/utils/functional.py", line 32, in __call__
    return self.__value__
AttributeError: 'ChannelPromise' object has no attribute '__value__'

During handling of the above exception, another exception occurred:

Traceback (most recent call last):
  File "/home/aa/.local/lib/python3.10/site-packages/kombu/connection.py", line 472, in _reraise_as_library_errors
    yield
  File "/home/aa/.local/lib/python3.10/site-packages/kombu/connection.py", line 459, in _ensure_connection
    return retry_over_time(
  File "/home/aa/.local/lib/python3.10/site-packages/kombu/utils/functional.py", line 318, in retry_over_time
    return fun(*args, **kwargs)
  File "/home/aa/.local/lib/python3.10/site-packages/kombu/connection.py", line 934, in _connection_factory
    self._connection = self._establish_connection()
  File "/home/aa/.local/lib/python3.10/site-packages/kombu/connection.py", line 860, in _establish_connection
    conn = self.transport.establish_connection()
  File "/home/aa/.local/lib/python3.10/site-packages/kombu/transport/pyamqp.py", line 203, in establish_connection
    conn.connect()
  File "/home/aa/.local/lib/python3.10/site-packages/amqp/connection.py", line 324, in connect
    self.transport.connect()
  File "/home/aa/.local/lib/python3.10/site-packages/amqp/transport.py", line 129, in connect
    self._connect(self.host, self.port, self.connect_timeout)
  File "/home/aa/.local/lib/python3.10/site-packages/amqp/transport.py", line 184, in _connect
    self.sock.connect(sa)
ConnectionRefusedError: [Errno 111] Connection refused

The above exception was the direct cause of the following exception:

Traceback (most recent call last):
  File "/home/aa/.local/lib/python3.10/site-packages/django/core/handlers/exception.py", line 55, in inner
    response = get_response(request)
  File "/home/aa/.local/lib/python3.10/site-packages/django/core/handlers/base.py", line 197, in _get_response
    response = wrapped_callback(request, *callback_args, **callback_kwargs)
  File "/media/aa/A/coffee/co/main/views.py", line 8, in index
    callme_form = handle_callme_form(request)
  File "/media/aa/A/coffee/co/main/form_generator.py", line 25, in handle_callme_form
    send_email.delay(name, phone, message)
  File "/home/aa/.local/lib/python3.10/site-packages/celery/app/task.py", line 444, in delay
    return self.apply_async(args, kwargs)
  File "/home/aa/.local/lib/python3.10/site-packages/celery/app/task.py", line 594, in apply_async
    return app.send_task(
  File "/home/aa/.local/lib/python3.10/site-packages/celery/app/base.py", line 801, in send_task
    amqp.send_task_message(P, name, message, **options)
  File "/home/aa/.local/lib/python3.10/site-packages/celery/app/amqp.py", line 518, in send_task_message
    ret = producer.publish(
  File "/home/aa/.local/lib/python3.10/site-packages/kombu/messaging.py", line 186, in publish
    return _publish(
  File "/home/aa/.local/lib/python3.10/site-packages/kombu/connection.py", line 556, in _ensured
    return fun(*args, **kwargs)
  File "/home/aa/.local/lib/python3.10/site-packages/kombu/messaging.py", line 195, in _publish
    channel = self.channel
  File "/home/aa/.local/lib/python3.10/site-packages/kombu/messaging.py", line 218, in _get_channel
    channel = self._channel = channel()
  File "/home/aa/.local/lib/python3.10/site-packages/kombu/utils/functional.py", line 34, in __call__
    value = self.__value__ = self.__contract__()
  File "/home/aa/.local/lib/python3.10/site-packages/kombu/messaging.py", line 234, in <lambda>
    channel = ChannelPromise(lambda: connection.default_channel)
  File "/home/aa/.local/lib/python3.10/site-packages/kombu/connection.py", line 953, in default_channel
    self._ensure_connection(**conn_opts)
  File "/home/aa/.local/lib/python3.10/site-packages/kombu/connection.py", line 458, in _ensure_connection
    with ctx():
  File "/usr/lib/python3.10/contextlib.py", line 153, in __exit__
    self.gen.throw(typ, value, traceback)
  File "/home/aa/.local/lib/python3.10/site-packages/kombu/connection.py", line 476, in _reraise_as_library_errors
    raise ConnectionError(str(exc)) from exc
kombu.exceptions.OperationalError: [Errno 111] Connection refused
2024-10-15 12:07:58,654 - Internal Server Error: /
Traceback (most recent call last):
  File "/home/aa/.local/lib/python3.10/site-packages/kombu/utils/functional.py", line 32, in __call__
    return self.__value__
AttributeError: 'ChannelPromise' object has no attribute '__value__'

During handling of the above exception, another exception occurred:

Traceback (most recent call last):
  File "/home/aa/.local/lib/python3.10/site-packages/kombu/connection.py", line 472, in _reraise_as_library_errors
    yield
  File "/home/aa/.local/lib/python3.10/site-packages/kombu/connection.py", line 459, in _ensure_connection
    return retry_over_time(
  File "/home/aa/.local/lib/python3.10/site-packages/kombu/utils/functional.py", line 318, in retry_over_time
    return fun(*args, **kwargs)
  File "/home/aa/.local/lib/python3.10/site-packages/kombu/connection.py", line 934, in _connection_factory
    self._connection = self._establish_connection()
  File "/home/aa/.local/lib/python3.10/site-packages/kombu/connection.py", line 860, in _establish_connection
    conn = self.transport.establish_connection()
  File "/home/aa/.local/lib/python3.10/site-packages/kombu/transport/pyamqp.py", line 203, in establish_connection
    conn.connect()
  File "/home/aa/.local/lib/python3.10/site-packages/amqp/connection.py", line 324, in connect
    self.transport.connect()
  File "/home/aa/.local/lib/python3.10/site-packages/amqp/transport.py", line 129, in connect
    self._connect(self.host, self.port, self.connect_timeout)
  File "/home/aa/.local/lib/python3.10/site-packages/amqp/transport.py", line 184, in _connect
    self.sock.connect(sa)
ConnectionRefusedError: [Errno 111] Connection refused

The above exception was the direct cause of the following exception:

Traceback (most recent call last):
  File "/home/aa/.local/lib/python3.10/site-packages/django/core/handlers/exception.py", line 55, in inner
    response = get_response(request)
  File "/home/aa/.local/lib/python3.10/site-packages/django/core/handlers/base.py", line 197, in _get_response
    response = wrapped_callback(request, *callback_args, **callback_kwargs)
  File "/media/aa/A/coffee/co/main/views.py", line 8, in index
    callme_form = handle_callme_form(request)
  File "/media/aa/A/coffee/co/main/form_generator.py", line 25, in handle_callme_form
    send_email.delay(name, phone, message)
  File "/home/aa/.local/lib/python3.10/site-packages/celery/app/task.py", line 444, in delay
    return self.apply_async(args, kwargs)
  File "/home/aa/.local/lib/python3.10/site-packages/celery/app/task.py", line 594, in apply_async
    return app.send_task(
  File "/home/aa/.local/lib/python3.10/site-packages/celery/app/base.py", line 801, in send_task
    amqp.send_task_message(P, name, message, **options)
  File "/home/aa/.local/lib/python3.10/site-packages/celery/app/amqp.py", line 518, in send_task_message
    ret = producer.publish(
  File "/home/aa/.local/lib/python3.10/site-packages/kombu/messaging.py", line 186, in publish
    return _publish(
  File "/home/aa/.local/lib/python3.10/site-packages/kombu/connection.py", line 556, in _ensured
    return fun(*args, **kwargs)
  File "/home/aa/.local/lib/python3.10/site-packages/kombu/messaging.py", line 195, in _publish
    channel = self.channel
  File "/home/aa/.local/lib/python3.10/site-packages/kombu/messaging.py", line 218, in _get_channel
    channel = self._channel = channel()
  File "/home/aa/.local/lib/python3.10/site-packages/kombu/utils/functional.py", line 34, in __call__
    value = self.__value__ = self.__contract__()
  File "/home/aa/.local/lib/python3.10/site-packages/kombu/messaging.py", line 234, in <lambda>
    channel = ChannelPromise(lambda: connection.default_channel)
  File "/home/aa/.local/lib/python3.10/site-packages/kombu/connection.py", line 953, in default_channel
    self._ensure_connection(**conn_opts)
  File "/home/aa/.local/lib/python3.10/site-packages/kombu/connection.py", line 458, in _ensure_connection
    with ctx():
  File "/usr/lib/python3.10/contextlib.py", line 153, in __exit__
    self.gen.throw(typ, value, traceback)
  File "/home/aa/.local/lib/python3.10/site-packages/kombu/connection.py", line 476, in _reraise_as_library_errors
    raise ConnectionError(str(exc)) from exc
kombu.exceptions.OperationalError: [Errno 111] Connection refused
2024-10-15 12:58:14,631 - No hostname was supplied. Reverting to default 'localhost'
2024-10-15 12:58:20,747 - Internal Server Error: /
Traceback (most recent call last):
  File "/home/aa/.local/lib/python3.10/site-packages/kombu/utils/functional.py", line 32, in __call__
    return self.__value__
AttributeError: 'ChannelPromise' object has no attribute '__value__'

During handling of the above exception, another exception occurred:

Traceback (most recent call last):
  File "/home/aa/.local/lib/python3.10/site-packages/kombu/connection.py", line 472, in _reraise_as_library_errors
    yield
  File "/home/aa/.local/lib/python3.10/site-packages/kombu/connection.py", line 459, in _ensure_connection
    return retry_over_time(
  File "/home/aa/.local/lib/python3.10/site-packages/kombu/utils/functional.py", line 318, in retry_over_time
    return fun(*args, **kwargs)
  File "/home/aa/.local/lib/python3.10/site-packages/kombu/connection.py", line 934, in _connection_factory
    self._connection = self._establish_connection()
  File "/home/aa/.local/lib/python3.10/site-packages/kombu/connection.py", line 860, in _establish_connection
    conn = self.transport.establish_connection()
  File "/home/aa/.local/lib/python3.10/site-packages/kombu/transport/pyamqp.py", line 203, in establish_connection
    conn.connect()
  File "/home/aa/.local/lib/python3.10/site-packages/amqp/connection.py", line 324, in connect
    self.transport.connect()
  File "/home/aa/.local/lib/python3.10/site-packages/amqp/transport.py", line 129, in connect
    self._connect(self.host, self.port, self.connect_timeout)
  File "/home/aa/.local/lib/python3.10/site-packages/amqp/transport.py", line 184, in _connect
    self.sock.connect(sa)
ConnectionRefusedError: [Errno 111] Connection refused

The above exception was the direct cause of the following exception:

Traceback (most recent call last):
  File "/home/aa/.local/lib/python3.10/site-packages/django/core/handlers/exception.py", line 55, in inner
    response = get_response(request)
  File "/home/aa/.local/lib/python3.10/site-packages/django/core/handlers/base.py", line 197, in _get_response
    response = wrapped_callback(request, *callback_args, **callback_kwargs)
  File "/media/aa/A/coffee/co/main/views.py", line 8, in index
    callme_form = handle_callme_form(request)
  File "/media/aa/A/coffee/co/main/form_generator.py", line 25, in handle_callme_form
    send_email.delay(name, phone, message)
  File "/home/aa/.local/lib/python3.10/site-packages/celery/app/task.py", line 444, in delay
    return self.apply_async(args, kwargs)
  File "/home/aa/.local/lib/python3.10/site-packages/celery/app/task.py", line 594, in apply_async
    return app.send_task(
  File "/home/aa/.local/lib/python3.10/site-packages/celery/app/base.py", line 801, in send_task
    amqp.send_task_message(P, name, message, **options)
  File "/home/aa/.local/lib/python3.10/site-packages/celery/app/amqp.py", line 518, in send_task_message
    ret = producer.publish(
  File "/home/aa/.local/lib/python3.10/site-packages/kombu/messaging.py", line 186, in publish
    return _publish(
  File "/home/aa/.local/lib/python3.10/site-packages/kombu/connection.py", line 556, in _ensured
    return fun(*args, **kwargs)
  File "/home/aa/.local/lib/python3.10/site-packages/kombu/messaging.py", line 195, in _publish
    channel = self.channel
  File "/home/aa/.local/lib/python3.10/site-packages/kombu/messaging.py", line 218, in _get_channel
    channel = self._channel = channel()
  File "/home/aa/.local/lib/python3.10/site-packages/kombu/utils/functional.py", line 34, in __call__
    value = self.__value__ = self.__contract__()
  File "/home/aa/.local/lib/python3.10/site-packages/kombu/messaging.py", line 234, in <lambda>
    channel = ChannelPromise(lambda: connection.default_channel)
  File "/home/aa/.local/lib/python3.10/site-packages/kombu/connection.py", line 953, in default_channel
    self._ensure_connection(**conn_opts)
  File "/home/aa/.local/lib/python3.10/site-packages/kombu/connection.py", line 458, in _ensure_connection
    with ctx():
  File "/usr/lib/python3.10/contextlib.py", line 153, in __exit__
    self.gen.throw(typ, value, traceback)
  File "/home/aa/.local/lib/python3.10/site-packages/kombu/connection.py", line 476, in _reraise_as_library_errors
    raise ConnectionError(str(exc)) from exc
kombu.exceptions.OperationalError: [Errno 111] Connection refused
2024-10-15 12:58:20,867 - Not Found: /favicon.ico
2024-10-15 12:58:48,531 - Internal Server Error: /
Traceback (most recent call last):
  File "/home/aa/.local/lib/python3.10/site-packages/kombu/utils/functional.py", line 32, in __call__
    return self.__value__
AttributeError: 'ChannelPromise' object has no attribute '__value__'

During handling of the above exception, another exception occurred:

Traceback (most recent call last):
  File "/home/aa/.local/lib/python3.10/site-packages/kombu/connection.py", line 472, in _reraise_as_library_errors
    yield
  File "/home/aa/.local/lib/python3.10/site-packages/kombu/connection.py", line 459, in _ensure_connection
    return retry_over_time(
  File "/home/aa/.local/lib/python3.10/site-packages/kombu/utils/functional.py", line 318, in retry_over_time
    return fun(*args, **kwargs)
  File "/home/aa/.local/lib/python3.10/site-packages/kombu/connection.py", line 934, in _connection_factory
    self._connection = self._establish_connection()
  File "/home/aa/.local/lib/python3.10/site-packages/kombu/connection.py", line 860, in _establish_connection
    conn = self.transport.establish_connection()
  File "/home/aa/.local/lib/python3.10/site-packages/kombu/transport/pyamqp.py", line 203, in establish_connection
    conn.connect()
  File "/home/aa/.local/lib/python3.10/site-packages/amqp/connection.py", line 324, in connect
    self.transport.connect()
  File "/home/aa/.local/lib/python3.10/site-packages/amqp/transport.py", line 129, in connect
    self._connect(self.host, self.port, self.connect_timeout)
  File "/home/aa/.local/lib/python3.10/site-packages/amqp/transport.py", line 184, in _connect
    self.sock.connect(sa)
ConnectionRefusedError: [Errno 111] Connection refused

The above exception was the direct cause of the following exception:

Traceback (most recent call last):
  File "/home/aa/.local/lib/python3.10/site-packages/django/core/handlers/exception.py", line 55, in inner
    response = get_response(request)
  File "/home/aa/.local/lib/python3.10/site-packages/django/core/handlers/base.py", line 197, in _get_response
    response = wrapped_callback(request, *callback_args, **callback_kwargs)
  File "/media/aa/A/coffee/co/main/views.py", line 8, in index
    callme_form = handle_callme_form(request)
  File "/media/aa/A/coffee/co/main/form_generator.py", line 25, in handle_callme_form
    send_email.delay(name, phone, message)
  File "/home/aa/.local/lib/python3.10/site-packages/celery/app/task.py", line 444, in delay
    return self.apply_async(args, kwargs)
  File "/home/aa/.local/lib/python3.10/site-packages/celery/app/task.py", line 594, in apply_async
    return app.send_task(
  File "/home/aa/.local/lib/python3.10/site-packages/celery/app/base.py", line 801, in send_task
    amqp.send_task_message(P, name, message, **options)
  File "/home/aa/.local/lib/python3.10/site-packages/celery/app/amqp.py", line 518, in send_task_message
    ret = producer.publish(
  File "/home/aa/.local/lib/python3.10/site-packages/kombu/messaging.py", line 186, in publish
    return _publish(
  File "/home/aa/.local/lib/python3.10/site-packages/kombu/connection.py", line 556, in _ensured
    return fun(*args, **kwargs)
  File "/home/aa/.local/lib/python3.10/site-packages/kombu/messaging.py", line 195, in _publish
    channel = self.channel
  File "/home/aa/.local/lib/python3.10/site-packages/kombu/messaging.py", line 218, in _get_channel
    channel = self._channel = channel()
  File "/home/aa/.local/lib/python3.10/site-packages/kombu/utils/functional.py", line 34, in __call__
    value = self.__value__ = self.__contract__()
  File "/home/aa/.local/lib/python3.10/site-packages/kombu/messaging.py", line 234, in <lambda>
    channel = ChannelPromise(lambda: connection.default_channel)
  File "/home/aa/.local/lib/python3.10/site-packages/kombu/connection.py", line 953, in default_channel
    self._ensure_connection(**conn_opts)
  File "/home/aa/.local/lib/python3.10/site-packages/kombu/connection.py", line 458, in _ensure_connection
    with ctx():
  File "/usr/lib/python3.10/contextlib.py", line 153, in __exit__
    self.gen.throw(typ, value, traceback)
  File "/home/aa/.local/lib/python3.10/site-packages/kombu/connection.py", line 476, in _reraise_as_library_errors
    raise ConnectionError(str(exc)) from exc
kombu.exceptions.OperationalError: [Errno 111] Connection refused
2024-10-15 12:58:48,679 - Not Found: /favicon.ico
2024-10-28 17:59:22,883 - /media/aa/A/coffee/co/main/tasks.py changed, reloading.
2024-10-28 17:59:25,005 - /media/aa/A/coffee/co/main/tasks.py changed, reloading.
2024-10-28 18:01:15,609 - /media/aa/A/coffee/co/co/settings.py changed, reloading.
2024-10-28 18:03:41,700 - /media/aa/A/coffee/co/main/form_generator.py changed, reloading.
2024-10-28 18:10:35,788 - /media/aa/A/coffee/co/co/settings.py changed, reloading.
2024-10-28 18:12:41,918 - /media/aa/A/coffee/co/main/tasks.py changed, reloading.
2024-10-28 18:12:58,082 - /media/aa/A/coffee/co/main/form_generator.py changed, reloading.
2024-10-28 18:13:03,117 - /media/aa/A/coffee/co/main/form_generator.py changed, reloading.
2024-10-28 18:14:42,759 - /media/aa/A/coffee/co/main/form_generator.py changed, reloading.
2024-10-28 18:19:33,478 - /media/aa/A/coffee/co/co/settings.py changed, reloading.
2024-10-28 18:19:46,693 - /media/aa/A/coffee/co/co/settings.py changed, reloading.
2024-10-28 18:20:56,564 - /media/aa/A/coffee/co/main/tasks.py changed, reloading.
2024-10-28 18:21:42,147 - /media/aa/A/coffee/co/main/tasks.py changed, reloading.
2024-10-28 18:25:48,521 - /media/aa/A/coffee/co/co/settings.py changed, reloading.
2024-10-28 18:29:24,282 - /media/aa/A/coffee/co/main/tasks.py changed, reloading.
2024-10-28 19:15:26,562 - /media/aa/A/coffee/co/co/celery.py changed, reloading.
2024-10-28 19:18:49,393 - /media/aa/A/coffee/co/co/celery.py changed, reloading.
2024-10-28 19:20:17,455 - /media/aa/A/coffee/co/co/settings.py changed, reloading.
2024-10-28 19:28:13,767 - /media/aa/A/coffee/co/co/settings.py changed, reloading.
2024-10-28 19:29:02,483 - /media/aa/A/coffee/co/co/settings.py changed, reloading.
2024-10-28 19:31:50,899 - /media/aa/A/coffee/co/main/tasks.py changed, reloading.
2024-10-28 19:32:27,379 - /media/aa/A/coffee/co/main/tasks.py changed, reloading.
2024-10-28 19:33:19,191 - /media/aa/A/coffee/co/co/settings.py changed, reloading.
2024-10-28 19:33:39,453 - /media/aa/A/coffee/co/co/settings.py changed, reloading.
2024-10-28 19:34:29,274 - /media/aa/A/coffee/co/co/settings.py changed, reloading.
2024-10-28 19:34:40,429 - /media/aa/A/coffee/co/co/settings.py changed, reloading.
2024-10-28 19:35:45,216 - /media/aa/A/coffee/co/co/settings.py changed, reloading.
2024-10-28 19:37:52,427 - /media/aa/A/coffee/co/co/settings.py changed, reloading.
2024-10-28 19:38:54,151 - /media/aa/A/coffee/co/co/settings.py changed, reloading.
2024-10-28 19:41:54,518 - /media/aa/A/coffee/co/co/settings.py changed, reloading.
2024-10-28 19:43:08,828 - /media/aa/A/coffee/co/co/settings.py changed, reloading.
2024-10-28 19:46:25,494 - /media/aa/A/coffee/co/main/form_generator.py changed, reloading.
2024-10-28 19:46:28,505 - /media/aa/A/coffee/co/main/form_generator.py changed, reloading.
2024-10-28 21:52:43,614 - /media/aa/A/coffee/co/co/settings.py changed, reloading.
2024-10-28 21:52:55,770 - /media/aa/A/coffee/co/co/settings.py changed, reloading.
2024-10-28 21:53:12,915 - /media/aa/A/coffee/co/co/settings.py changed, reloading.
2024-10-28 21:53:18,937 - /media/aa/A/coffee/co/co/settings.py changed, reloading.
2024-10-28 21:57:40,101 - /media/aa/A/coffee/co/co/settings.py changed, reloading.
